<sdf version='1.6'>
  <model name='gurdy'>
    <link name='x_axis_link'>
      <pose frame=''>0 0 0.0 0 -0 0</pose>
      <inertial>
        <pose frame=''>0 0 0.002273 0 -0 0</pose>
        <mass>1.1</mass>
        <inertia>
          <ixx>9.92432e-05</ixx>
          <ixy>0</ixy>
          <ixz>0</ixz>
          <iyy>9.92432e-05</iyy>
          <iyz>0</iyz>
          <izz>4.29167e-05</izz>
        </inertia>
      </inertial>
      <collision name='x_axis_link_collision'>
        <pose frame=''>0 0 0 0 -0 0</pose>
        <geometry>
          <box>
            <size>2.5 2.5 0.05</size>
          </box>
        </geometry>
        <surface>
          <contact>
            <ode/>
          </contact>
          <friction>
            <ode>
              <mu>10</mu>
              <mu2>10</mu2>
            </ode>
          </friction>
        </surface>
      </collision>
      <visual name='x_axis_link_visual'>
        <pose frame=''>0 0 0 0 -0 0</pose>
        <geometry>
          <box>
            <size>3 3 0.05</size>
          </box>
        </geometry>
        <material>
          <script>
            <name>Gazebo/Red</name>
            <uri>file://media/materials/scripts/gazebo.material</uri>
          </script>
        </material>
      </visual>
      <visual name='x_axis_link_fixed_joint_lump__entity_link_visual_1'>
        <pose frame=''>0 0 0.25 0 -0 0</pose>
        <geometry>
          <cylinder>
            <length>0.50</length>
            <radius>0.025</radius>
          </cylinder>
        </geometry>
        <material>
          <script>
            <name>Gazebo/Blue</name>
            <uri>file://media/materials/scripts/gazebo.material</uri>
          </script>
        </material>
      </visual>
      <velocity_decay/>
      <gravity>1</gravity>
      <velocity_decay/>
    </link>
    <joint name='x_axis_joint' type='prismatic'>
      <child>x_axis_link</child>
      <parent>world</parent>
      <axis>
        <xyz>1 0 0</xyz>
        <limit>
          <lower>-5</lower>
          <upper>5</upper>
          <effort>10000</effort>
          <velocity>1</velocity>
        </limit>
        <dynamics>
          <spring_reference>0</spring_reference>
          <spring_stiffness>0</spring_stiffness>
        </dynamics>
        <use_parent_model_frame>1</use_parent_model_frame>
      </axis>
    </joint>

    <link name='z_axis_link'>
      <pose frame=''>0 0 0.51 0 -0 0</pose>
      <inertial>
        <pose frame=''>0 0 0 0 -0 0</pose>
        <mass>0.1</mass>
        <inertia>
          <ixx>4.16667e-05</ixx>
          <ixy>0</ixy>
          <ixz>0</ixz>
          <iyy>4.16667e-05</iyy>
          <iyz>0</iyz>
          <izz>4.16667e-05</izz>
        </inertia>
      </inertial>
      <collision name='z_axis_link_collision'>
        <pose frame=''>0 0 0 0 -0 0</pose>
        <geometry>
          <cylinder>
            <length>0.05</length>
            <radius>0.5</radius>
          </cylinder>
        </geometry>
        <surface>
          <contact>
            <ode/>
          </contact>
          <friction>
            <ode>
              <mu>10</mu>
              <mu2>10</mu2>
            </ode>
          </friction>
        </surface>
      </collision>
      <visual name='z_axis_link_visual'>
        <pose frame=''>0 0 0 0 -0 0</pose>
        <geometry>
          <cylinder>
            <length>0.05</length>
            <radius>0.5</radius>
          </cylinder>
        </geometry>
        <material>
          <script>
            <name>Gazebo/Green</name>
            <uri>file://media/materials/scripts/gazebo.material</uri>
          </script>
        </material>
      </visual>
      <gravity>1</gravity>
      <velocity_decay/>
    </link>
    <joint name='z_axis_joint' type='ball'>
      <child>z_axis_link</child>
      <parent>x_axis_link</parent>
      <axis>
        <xyz>0 0 1</xyz>
        <limit>
          <lower>-5</lower>
          <upper>5</upper>
          <effort>10000</effort>
          <velocity>1</velocity>
        </limit>
        <dynamics>
          <spring_reference>0</spring_reference>
          <spring_stiffness>0</spring_stiffness>
        </dynamics>
        <use_parent_model_frame>1</use_parent_model_frame>
      </axis>
    </joint>
    <static>0</static>
    <plugin name='gazebo_ros_control' filename='libgazebo_ros_control.so'>
      <robotSimType>gazebo_ros_control/DefaultRobotHWSim</robotSimType>
      <legacyModeNS>1</legacyModeNS>
    </plugin>
  </model>
</sdf>

